Workbook

Sheet Лист1
A1: I. Mahalla haqida umumiy ma’lumot | C1: Jami ko‘rsatkichlar | D1: A.Navoiy | E1: Bog‘izilol | F1: Bunyodkor | G1: Gultepa | H1: Zargar | I1: Zax-ariq | J1: Istiqbol | K1: Kalas | L1: Qizg‘aldoq | M1: Majnuntol | N1: Ma’rifat | O1: Nurxayot | P1: Sohibkor | Q1: Uch chinor | R1: Fayzobod | S1: Xalimko‘p | T1: Xiyobon | U1: Chuvalachi | V1: Shirin | W1: Avliyo ota | X1: Ayri ota | Y1: Bog‘bon | Z1: Gʻishtko‘prik | AA1: Darxon | AB1: Ibrat | AC1: Ikbol | AD1: Qashqarliq | AE1: Mustaqillik | AF1: Oydin xayot | AG1: Raxbarobod | AH1: Sabzavot | AI1: Sarke | AJ1: Sirg‘ali | AK1: Tutzor | AL1: Axillik | AM1: Baxor | AN1: Kensoy | AO1: Korasaroy | AP1: Ko‘k terak | AQ1: Qir-ariq | AR1: Obodlik | AS1: Ozodlik | AT1: Okibat | AU1: Tinchlik | AV1: Uch sada | AW1: Xasanboy guzar | AX1: Hasanboy | AY1: Huvaydo | AZ1: Beruniy | BA1: Beshterak | BB1: Diydor | BC1: Zarbdor | BD1: Ko‘ksaroy | BE1: Ko‘xinur | BF1: Kushkundi | BG1: Qorabo‘rik | BH1: Oqtom | BI1: Oqtosh | BJ1: Oltin tepa | BK1: O‘rikzor | BL1: Chig‘atoy | BM1: Shamsiobod | BN1: Yangi hayot
A2: 1 | B2: Mahalla soni | C2: =SUM(D2:BN2) -> 63 | D2: 1 | E2: 1 | F2: 1 | G2: 1 | H2: 1 | I2: 1 | J2: 1 | K2: 1 | L2: 1 | M2: 1 | N2: 1 | O2: 1 | P2: 1 | Q2: 1 | R2: 1 | S2: 1 | T2: 1 | U2: 1 | V2: 1 | W2: 1 | X2: 1 | Y2: 1 | Z2: 1 | AA2: 1 | AB2: 1 | AC2: 1 | AD2: 1 | AE2: 1 | AF2: 1 | AG2: 1 | AH2: 1 | AI2: 1 | AJ2: 1 | AK2: 1 | AL2: 1 | AM2: 1 | AN2: 1 | AO2: 1 | AP2: 1 | AQ2: 1 | AR2: 1 | AS2: 1 | AT2: 1 | AU2: 1 | AV2: 1 | AW2: 1 | AX2: 1 | AY2: 1 | AZ2: 1 | BA2: 1 | BB2: 1 | BC2: 1 | BD2: 1 | BE2: 1 | BF2: 1 | BG2: 1 | BH2: 1 | BI2: 1 | BJ2: 1 | BK2: 1 | BL2: 1 | BM2: 1 | BN2: 1
A3: =+A2+1 -> 2 | B3: Umumiy yer maydoni (ga) | C3: =SUM(D3:BN3) -> 11712.95 | D3: 106.5 | E3: 279.3 | F3: 318.2 | G3: 365.5 | H3: 188 | I3: 272.7 | J3: 450 | K3: 86 | L3: 281 | M3: 160 | N3: 93.7 | O3: 285 | P3: 90.6 | Q3: 118.2 | R3: 39.7 | S3: 95.5 | T3: 135 | U3: 410 | V3: 390 | W3: 90.9 | X3: 241.45 | Y3: 356.7 | Z3: 564.2 | AA3: 564.2 | AB3: 564.2 | AC3: 104.1 | AD3: 21.1 | AE3: 382 | AF3: 184 | AG3: 297.4 | AH3: 40 | AI3: 91.2 | AJ3: 223 | AK3: 52 | AL3: 62 | AM3: 95.1 | AN3: 330 | AO3: 225 | AP3: 78.3 | AQ3: 571 | AR3: 82.6 | AS3: 11.9 | AT3: 106.23 | AU3: 10.5 | AV3: 125 | AW3: 330 | AX3: 420.4 | AY3: 113.6 | AZ3: 40.4 | BA3: 44.56 | BB3: 48.1 | BC3: 264.51 | BD3: 81.12 | BE3: 48.8 | BF3: 81.12 | BG3: 82.1 | BH3: 48.49 | BI3: 41.61 | BJ3: 95.1 | BK3: 108 | BL3: 135.66 | BM3: 72.4 | BN3: 18
A4: =+A3+1 -> 3 | B4: Ixtisoslashuvi (drayveri) | C4: 63 | D4: Xizmat ko‘rsatish, savdo sotiq | E4: Bog‘dorchilik, chorvachilik | F4: Xizmatko‘rsatish, ishlab chiqarish | G4: Chorvachilik, dehqonchilik | H4: Chorvachilik, dehqonchilik | I4: Bog‘dorchilik va kasanachilik | J4: Chorvachilik, dehqonchilik | K4: Chorvachilik, dehqonchilik | L4: Tikuvchilik, issiqxonachilik | M4: Chorvachilik, dehqonchilik | N4: Tikuvchilik | O4: Chorvachilik, dehqonchilik | P4: Xizmatko‘rsatish, ishlab chiqarish | Q4: Chorvachilik, dehqonchilik | R4: Xizmatko‘rsatish, ishlab chiqarish | S4: Chorvachilik, dehqonchilik | T4: Chorvachilik, dehqonchilik | U4: Bog‘dorchilik, chorvachilik | V4: Bog‘dorchilik, chorvachilik | W4: Chorvachilik, dehqonchilik | X4: Dehqonchilik | Y4: Xizmat ko‘rsatish, dehqonchilik | Z4: Chorvachilik | AA4: Chorvachilik, dehqonchilik | AB4: Chorvachilik, dehqonchilik | AC4: Xizmatko‘rsatish, dehqonchilik | AD4: Xizmatko‘rsatish, dehqonchilik | AE4: Chorvachilik, dehqonchilik | AF4: Xizmat ko‘rsatish, chorvachilik | AG4: Xizmat ko‘rsatish, chorvachilik | AH4: Xizmat ko‘rsatish, chorvachilik | AI4: Xizmat ko‘rsatish, chorvachilik | AJ4: Xizmat ko‘rsatish, chorvachilik | AK4: Xizmat ko‘rsatish, chorvachilik | AL4: Chorvachilik, tikuvchilik | AM4: Issiqxona, chorvachilik | AN4: Qishloqxo‘jaligi | AO4: Meva sabzavotchilik | AP4: Xizmatko‘rsatish, savdosotiq | AQ4: Chorvachilik, dehqonchilik | AR4: Sanoat ishlab chiqarish | AS4: Tikuvchilik, xizmat ko‘rsatish | AT4: Ishlab chiqarish, xizmatko‘rsatish | AU4: Qishloqxo‘jaligi | AV4: Qishloqxo‘jaligi | AW4: Qishloqxo‘jaligi | AX4: Qishloqxo‘jaligi | AY4: Qishloqxo‘jaligi | AZ4: Chorvachilik, dehqonchilik | BA4: Tikuvchilik | BB4: Ishlab chiqarish, xizmat ko‘rsatish va issiqxona | BC4: Chorvachilik, dehqonchilik | BD4: Xizmatko‘rsatish, tikuvchilik, chorvachilik | BE4: Chorvachilik, dehqonchilik | BF4: Dehqonchilik, issiqxona va tikuvchilik | BG4: Chorvachilik, dehqonchilik, issiqxonada ko‘chatchilik | BH4: Qishloqxo‘jaligi | BI4: Chorvachilik, dehqonchilik | BJ4: Chorvachilik, dehqonchilik | BK4: Chorvachilik, dehqonchilik | BL4: Chorvachilik, dehqonchilik | BM4: Chorvachilik, dehqonchilik | BN4: Chorvachilik, dehqonchilik
A5: =+A4+1 -> 4 | B5: Qo‘shni davlatlar bilan chegarasi mavjud mahalla soni | C5: =SUM(D5:BN5) -> 21 | D5: 0 | E5: 1 | F5: 0 | G5: 1 | H5: 1 | I5: 0 | J5: 1 | K5: 1 | L5: 0 | M5: 1 | N5: 0 | O5: 1 | P5: 0 | Q5: 0 | R5: 0 | S5: 0 | T5: 0 | U5: 1 | V5: 1 | W5: 0 | X5: 0 | Y5: 0 | Z5: 1 | AA5: 0 | AB5: 0 | AC5: 0 | AD5: 0 | AE5: 1 | AF5: 0 | AG5: 0 | AH5: 0 | AI5: 1 | AJ5: 1 | AK5: 0 | AL5: 0 | AM5: 0 | AN5: 1 | AO5: 0 | AP5: 0 | AQ5: 0 | AR5: 0 | AS5: 0 | AT5: 0 | AU5: 0 | AV5: 0 | AW5: 0 | AX5: 0 | AY5: 0 | AZ5: 1 | BA5: 0 | BB5: 0 | BC5: 0 | BD5: 0 | BE5: 0 | BF5: 1 | BG5: 1 | BH5: 1 | BI5: 1 | BJ5: 1 | BK5: 1 | BL5: 0 | BM5: 0 | BN5: 0
A6: 5 | B6: Ko‘chalar soni (a+b+s), shundan: | C6: =SUBTOTAL(9,D6:BN6) -> 1671 | D6: =SUM(D7:D9) -> 39 | E6: =SUM(E7:E9) -> 16 | F6: =SUM(F7:F9) -> 85 | G6: =SUM(G7:G9) -> 19 | H6: =SUM(H7:H9) -> 41 | I6: =SUM(I7:I9) -> 51 | J6: =SUM(J7:J9) -> 10 | K6: =SUM(K7:K9) -> 29 | ... BN6: =SUM(BN7:BN9) -> 13
A7: =+A6+1 -> 6 | B7: a) asosiy ko‘chalar soni | C7: =SUM(D7:BN7) -> 510 | D7: 15 | E7: 13 | F7: 3 | G7: 10 | H7: 8 | I7: 17 | K7: 3 | L7: 14 | M7: 2 | N7: 5 | O7: 6 | P7: 4 | Q7: 9 | R7: 11 | S7: 9 | T7: 3 | U7: 9 | V7: 11 | W7: 14 | X7: 11 | Y7: 7 | Z7: 12 | AA7: 6 | AB7: 3 | AC7: 33 | AD7: 8 | AE7: 19 | AF7: 10 | AG7: 11 | AH7: 5 | AI7: 21 | AJ7: 6 | AK7: 14 | AL7: 9 | AM7: 4 | AN7: 5 | AO7: 10 | AP7: 9 | AQ7: 5 | AR7: 5 | AS7: 1 | AT7: 1 | AU7: 3 | AV7: 0 | AW7: 6 | AX7: 15 | AY7: 4 | AZ7: 6 | BA7: 7 | BB7: 8 | BC7: 6 | BD7: 8 | BE7: 1 | BF7: 8 | BG7: 14 | BH7: 13 | BI7: 4 | BJ7: 4 | BK7: 5 | BL7: 5 | BM7: 10 | BN7: 2
A8: =+A7+1 -> 7 | B8: b) tor ko‘chalar soni | C8: =SUM(D8:BN8) -> 592 | D8: 22 | E8: 0 | F8: 76 | G8: 9 | H8: 26 | I8: 26 | J8: 10 | K8: 21 | L8: 19 | M8: 3 | N8: 16 | O8: 11 | P8: 17 | Q8: 14 | R8: 3 | S8: 14 | T8: 0 | U8: 0 | V8: 1 | W8: 15 | X8: 23 | Y8: 3 | Z8: 1 | AA8: 7 | AB8: 3 | AC8: 2 | AD8: 3 | AE8: 0 | AF8: 10 | AG8: 18 | AH8: 6 | AI8: 0 | AJ8: 0 | AK8: 7 | AL8: 3 | AM8: 0 | AN8: 6 | AO8: 7 | AP8: 0 | AQ8: 26 | AR8: 0 | AS8: 31 | AT8: 5 | AU8: 4 | AV8: 14 | AW8: 30 | AX8: 8 | AY8: 6 | AZ8: 0 | BA8: 2 | BB8: 2 | BC8: 9 | BD8: 4 | BE8: 6 | BF8: 4 | BG8: 6 | BH8: 5 | BI8: 4 | BJ8: 0 | BK8: 14 | BL8: 9 | BM8: 0 | BN8: 1
A9: =+A8+1 -> 8 | B9: s) berk ko‘chalar soni | C9: =SUM(D9:BN9) -> 569 | D9: 2 | E9: 3 | F9: 6 | G9: 0 | H9: 7 | I9: 8 | J9: 0 | K9: 5 | L9: 8 | M9: 2 | N9: 1 | O9: 20 | P9: 2 | Q9: 9 | R9: 0 | S9: 9 | T9: 1 | U9: 1 | V9: 0 | W9: 22 | X9: 6 | Y9: 38 | Z9: 19 | AA9: 12 | AB9: 5 | AC9: 1 | AD9: 4 | AE9: 14 | AF9: 24 | AG9: 2 | AH9: 15 | AI9: 7 | AJ9: 24 | AK9: 0 | AL9: 7 | AM9: 49 | AN9: 1 | AO9: 5 | AP9: 3 | AQ9: 7 | AR9: 0 | AS9: 0 | AT9: 1 | AU9: 0 | AV9: 15 | AW9: 5 | AX9: 5 | AY9: 1 | AZ9: 11 | BA9: 4 | BB9: 0 | BC9: 2 | BD9: 7 | BE9: 13 | BF9: 7 | BG9: 6 | BH9: 25 | BI9: 38 | BJ9: 49 | BK9: 3 | BL9: 13 | BM9: 5 | BN9: 10
A10: =+A9+1 -> 9 | B10: Yakka tartibdagi uylar soni | C10: =SUM(D10:BN10) -> 51271 | D10: 1131 | E10: 1085 | F10: 1046 | G10: 720 | H10: 644 | I10: 741 | J10: 845 | K10: 695 | L10: 1754 | M10: 473 | N10: 656 | O10: 712 | P10: 665 | Q10: 1040 | R10: 1055 | S10: 1042 | T10: 691 | U10: 614 | V10: 656 | W10: 1085 | X10: 1046 | Y10: 896 | Z10: 864 | AA10: 600 | AB10: 647 | AC10: 867 | AD10: 593 | AE10: 1009 | AF10: 700 | AG10: 676 | AH10: 801 | AI10: 732 | AJ10: 534 | AK10: 899 | AL10: 720 | AM10: 644 | AN10: 806 | AO10: 1054 | AP10: 770 | AQ10: 1112 | AR10: 503 | AS10: 850 | AT10: 1047 | AU10: 654 | AV10: 1045 | AW10: 920 | AX10: 727 | AY10: 957 | AZ10: 514 | BA10: 627 | BB10: 721 | BC10: 717 | BD10: 729 | BE10: 655 | BF10: 652 | BG10: 615 | BH10: 1088 | BI10: 1047 | BJ10: 1154 | BK10: 766 | BL10: 818 | BM10: 517 | BN10: 628
A11: =+A10+1 -> 10 | B11: Ko‘p qavatli uylar soni | C11: =SUM(D11:BN11) -> 111 | D11: 8 | E11: 0 | F11: 4 | G11: 0 | H11: 0 | I11: 0 | J11: 5 | K11: 0 | L11: 22 | M11: 0 | N11: 0 | O11: 0 | P11: 0 | Q11: 0 | R11: 4 | S11: 0 | T11: 0 | U11: 0 | V11: 0 | W11: 1 | X11: 0 | Y11: 0 | Z11: 0 | AA11: 0 | AB11: 0 | AC11: 0 | AD11: 0 | AE11: 0 | AF11: 0 | AG11: 0 | AH11: 0 | AI11: 0 | AJ11: 0 | AK11: 0 | AL11: 0 | AM11: 0 | AN11: 8 | AO11: 0 | AP11: 0 | AQ11: 0 | AR11: 2 | AS11: 31 | AT11: 9 | AU11: 0 | AV11: 0 | AW11: 0 | AX11: 0 | AY11: 7 | AZ11: 0 | BA11: 0 | BB11: 6 | BC11: 0 | BD11: 0 | BE11: 0 | BF11: 0 | BG11: 0 | BH11: 4 | BI11: 0 | BJ11: 0 | BK11: 0 | BL11: 0 | BM11: 0 | BN11: 0
A12: =+A11+1 -> 11 | B12: Xonadonlar soni | C12: =SUBTOTAL(9,D12:BN12) -> 48454 | D12: 1131 | E12: 1055 | F12: 1046 | G12: 720 | H12: 644 | I12: 741 | J12: 745 | K12: 695 | L12: 1375 | M12: 473 | N12: 656 | O12: 712 | P12: 665 | Q12: 1040 | R12: 568 | S12: 1042 | T12: 691 | U12: 614 | V12: 656 | W12: 1033 | X12: 1046 | Y12: 896 | Z12: 864 | AA12: 600 | AB12: 647 | AC12: 867 | AD12: 593 | AE12: 1009 | AF12: 700 | AG12: 676 | AH12: 801 | AI12: 732 | AJ12: 534 | AK12: 899 | AL12: 720 | AM12: 644 | AN12: 598 | AO12: 1054 | AP12: 770 | AQ12: 1112 | AR12: 465 | AS12: 31 | AT12: 753 | AU12: 654 | AV12: 1045 | AW12: 920 | AX12: 727 | AY12: 751 | AZ12: 514 | BA12: 627 | BB12: 613 | BC12: 717 | BD12: 729 | BE12: 655 | BF12: 652 | BG12: 615 | BH12: 992 | BI12: 1047 | BJ12: 1154 | BK12: 766 | BL12: 818 | BM12: 517 | BN12: 628
D13: 1234 | E13: 1055 | F13: 1076 | G13: 720 | H13: 644 | I13: 741 | J13: 845 | K13: 695 | L13: 1754 | M13: 473 | N13: 656 | O13: 712 | P13: 665 | Q13: 1040 | R13: 1055 | S13: 1042 | T13: 691 | U13: 614 | V13: 656 | W13: 1085 | X13: 1046 | Y13: 896 | Z13: 864 | AA13: 600 | AB13: 647 | AC13: 867 | AD13: 593 | AE13: 1009 | AF13: 700 | AG13: 676 | AH13: 801 | AI13: 732 | AJ13: 534 | AK13: 899 | AL13: 720 | AM13: 644 | AN13: 806 | AO13: 1054 | AP13: 770 | AQ13: 1112 | AR13: 503 | AS13: 850 | AT13: 1047 | AU13: 654 | AV13: 1045 | AW13: 920 | AX13: 727 | AY13: 957 | AZ13: 514 | BA13: 627 | BB13: 721 | BC13: 717 | BD13: 729 | BE13: 655 | BF13: 652 | BG13: 615 | BH13: 1088 | BI13: 1047 | BJ13: 1154 | BK13: 766 | BL13: 818 | BM13: 517 | BN13: 628
A14: =+A12+1 -> 12 | B14: shundan, ko‘p qavatli uylardagi xonadonlar | C14: =SUM(D14:BN14) -> 2920 | D14: 103 | E14: 0 | F14: 30 | G14: 0 | H14: 0 | I14: 0 | J14: 100 | K14: 0 | L14: 379 | M14: 0 | N14: 0 | O14: 0 | P14: 0 | Q14: 0 | R14: 487 | S14: 0 | T14: 0 | U14: 0 | V14: 0 | W14: 52 | X14: 0 | Y14: 0 | Z14: 0 | AA14: 0 | AB14: 0 | AC14: 0 | AD14: 0 | AE14: 0 | AF14: 0 | AG14: 0 | AH14: 0 | AI14: 0 | AJ14: 0 | AK14: 0 | AL14: 0 | AM14: 0 | AN14: 208 | AO14: 0 | AP14: 0 | AQ14: 0 | AR14: 38 | AS14: 819 | AT14: 294 | AU14: 0 | AV14: 0 | AW14: 0 | AX14: 0 | AY14: 206 | AZ14: 0 | BA14: 0 | BB14: 108 | BC14: 0 | BD14: 0 | BE14: 0 | BF14: 0 | BG14: 0 | BH14: 96 | BI14: 0 | BJ14: 0 | BK14: 0 | BL14: 0 | BM14: 0 | BN14: 0
A15: =+A14+1 -> 13 | B15: Oilalar soni | C15: =SUBTOTAL(9,D15:BN15) -> 67984 | D15: 1593 | E15: 1176 | F15: 1076 | G15: 960 | H15: 920 | I15: 609 | J15: 805 | K15: 1046 | L15: 1448 | M15: 1485 | N15: 950 | O15: 935 | P15: 910 | Q15: 985 | R15: 1176 | S15: 953 | T15: 1210 | U15: 721 | V15: 1015 | W15: 1125 | X15: 859 | Y15: 1016 | Z15: 664 | AA15: 937 | AB15: 1217 | AC15: 714 | AD15: 735 | AE15: 890 | AF15: 2336 | AG15: 1616 | AH15: 1389 | AI15: 733 | AJ15: 960 | AK15: 1297 | AL15: 1165 | AM15: 585 | AN15: 980 | AO15: 1012 | AP15: 1803 | AQ15: 1334 | AR15: 1215 | AS15: 1303 | AT15: 955 | AU15: 1009 | AV15: 767 | AW15: 679 | AX15: 1015 | AY15: 760 | AZ15: 860 | BA15: 1157 | BB15: 1745 | BC15: 1562 | BD15: 1175 | BE15: 1557 | BF15: 1160 | BG15: 1216 | BH15: 1062 | BI15: 1263 | BJ15: 909 | BK15: 978 | BL15: 664 | BM15: 980 | BN15: 653
A16: =+A15+1 -> 14 | B16: Yakka tartibdagi xonadonlarda | C16: =SUM(D16:BN16) -> 67778 | D16: 1490 | E16: 1176 | F16: 1072 | G16: 960 | H16: 920 | I16: 609 | J16: 805 | K16: 1041 | L16: 1448 | M16: 1463 | N16: 950 | O16: 935 | P16: 910 | Q16: 985 | R16: 1176 | S16: 949 | T16: 1210 | U16: 721 | V16: 1015 | W16: 1125 | X16: 858 | Y16: 1016 | Z16: 664 | AA16: 937 | AB16: 1217 | AC16: 714 | AD16: 735 | AE16: 890 | AF16: 2336 | AG16: 1616 | AH16: 1389 | AI16: 733 | AJ16: 960 | AK16: 1297 | AL16: 1165 | AM16: 585 | AN16: 980 | AO16: 1004 | AP16: 1803 | AQ16: 1334 | AR16: 1215 | AS16: 1301 | AT16: 924 | AU16: 1000 | AV16: 767 | AW16: 679 | AX16: 1015 | AY16: 760 | AZ16: 853 | BA16: 1157 | BB16: 1745 | BC16: 1556 | BD16: 1175 | BE16: 1557 | BF16: 1160 | BG16: 1216 | BH16: 1062 | BI16: 1259 | BJ16: 909 | BK16: 978 | BL16: 664 | BM16: 980 | BN16: 653
A17: =+A16+1 -> 15 | B17: Ko‘p qavatli uylardgi xonadonlarda | C17: =SUM(D17:BN17) -> 111 | D17: =+D11 -> 8 | E17: =+E11 -> 0 | F17: =+F11 -> 4 | G17: =+G11 -> 0 | H17: =+H11 -> 0 | I17: =+I11 -> 0 | J17: 5 | K17: =+K11 -> 0 | L17: =+L11 -> 22 | M17: =+M11 -> 0 | N17: =+N11 -> 0 | O17: =+O11 -> 0 | P17: =+P11 -> 0 | Q17: =+Q11 -> 0 | R17: =+R11 -> 4 | ... BN17: =+BN11 -> 0
A18: =+A17+1 -> 16 | B18: Tomorqasi bor xonadonlar soni | C18: =SUBTOTAL(9,D18:BN18) -> 0
A19: =+A18+1 -> 17 | B19: Umumiy tomorqa maydoni (ga) | C19: =SUM(D19:BN19) -> 333.86667 | D19: 5.35 | E19: 8.8416667 | F19: 6.2 | G19: 5.7583333 | H19: 5.3666667 | I19: 6.175 | J19: 5.925 | K19: 4.125 | L19: 5.8333333 | M19: 3.6833333 | N19: 4.1416667 | O19: 3.9166667 | P19: 4.3416667 | Q19: 6.75 | R19: 4.0833333 | S19: 6.75 | T19: 4.3 | U19: 4.8583333 | V19: 5.4666667 | W19: 6.0166667 | X19: 7.9166667 | Y19: 5.6416667 | Z19: 7.2 | AA19: 3.5333333 | AB19: 3 | AC19: 2.9166667 | AD19: 3.7083333 | AE19: 7.6166667 | AF19: 5.475 | AG19: 5 | AH19: 6.175 | AI19: 6.1 | AJ19: 3.5833333 | AK19: 6.475 | AL19: 4.8333333 | AM19: 5.3416667 | AN19: 4.3416667 | AO19: 8.125 | AP19: 5.2916667 | AQ19: 7.1416667 | AR19: 2.8416667 | AS19: 0 | AT19: 3.4833333 | AU19: 2.625 | AV19: 8.7083333 | AW19: 7.6666667 | AX19: 6.0583333 | AY19: 5.8166667 | AZ19: 3.8083333 | BA19: 4.55 | BB19: 4.7333333 | BC19: 5.4833333 | BD19: 4.8666667 | BE19: 4.3 | BF19: 4.8666667 | BG19: 5.125 | BH19: 7.2 | BI19: 8.125 | BJ19: 8.025 | BK19: 5 | BL19: 6.5916667 | BM19: 4.025 | BN19: 2.6666667
A20: =+A19+1 -> 18 | B20: Tomorqadan 3 marta hosil oladigan xonadonlar soni | C20: =SUM(D20:BN20) -> 152 | D20: 3 | E20: 2 | F20: 3 | G20: 2 | H20: 3 | I20: 2 | J20: 3 | K20: 2 | L20: 2 | M20: 2 | N20: 3 | O20: 2 | P20: 3 | Q20: 2 | R20: 3 | S20: 2 | T20: 3 | U20: 2 | V20: 2 | W20: 2 | X20: 3 | Y20: 2 | Z20: 3 | AA20: 2 | AB20: 3 | AC20: 2 | AD20: 3 | AE20: 2 | AF20: 2 | AG20: 2 | AH20: 3 | AI20: 2 | AJ20: 3 | AK20: 2 | AL20: 3 | AM20: 2 | AN20: 3 | AO20: 2 | AP20: 2 | AQ20: 2 | AR20: 3 | AS20: 2 | AT20: 3 | AU20: 2 | AV20: 3 | AW20: 2 | AX20: 3 | AY20: 2 | AZ20: 2 | BA20: 2 | BB20: 3 | BC20: 2 | BD20: 3 | BE20: 2 | BF20: 3 | BG20: 2 | BH20: 3 | BI20: 2 | BJ20: 2 | BK20: 2 | BL20: 3 | BM20: 2 | BN20: 3
A21: =+A20+1 -> 19 | B21: Dala tomorqasi (qo‘shimcha tomorqa) mavjud xonadonlar soni | C21: =SUM(D21:BN21) -> 0 | D21: 0 | E21: 0 | F21: 0 | G21: 0 | H21: 0 | I21: 0 | J21: 0 | K21: 0 | L21: 0 | M21: 0 | N21: 0 | O21: 0 | P21: 0 | Q21: 0 | R21: 0 | S21: 0 | T21: 0 | U21: 0 | V21: 0 | W21: 0 | X21: 0 | Y21: 0 | Z21: 0 | AA21: 0 | AB21: 0 | AC21: 0 | AD21: 0 | AE21: 0 | AF21: 0 | AG21: 0 | AH21: 0 | AI21: 0 | AJ21: 0 | AK21: 0 | AL21: 0 | AM21: 0 | AN21: 0 | AO21: 0 | AP21: 0 | AQ21: 0 | AR21: 0 | AS21: 0 | AT21: 0 | AU21: 0 | AV21: 0 | AW21: 0 | AX21: 0 | AY21: 0 | AZ21: 0 | BA21: 0 | BB21: 0 | BC21: 0 | BD21: 0 | BE21: 0 | BF21: 0 | BG21: 0 | BH21: 0 | BI21: 0 | BJ21: 0 | BK21: 0 | BL21: 0 | BM21: 0 | BN21: 0
A22: 20 | B22: Ijara asosida olingan yerlari (dexqon xo‘jalik) mavjud xonadonlar soni | C22: =SUM(D22:BN22) -> 0 | D22: 0 | E22: 0 | F22: 0 | G22: 0 | H22: 0 | I22: 0 | J22: 0 | K22: 0 | L22: 0 | M22: 0 | N22: 0 | O22: 0 | P22: 0 | Q22: 0 | R22: 0 | S22: 0 | T22: 0 | U22: 0 | V22: 0 | W22: 0 | X22: 0 | Y22: 0 | Z22: 0 | AA22: 0 | AB22: 0 | AC22: 0 | AD22: 0 | AE22: 0 | AF22: 0 | AG22: 0 | AH22: 0 | AI22: 0 | AJ22: 0 | AK22: 0 | AL22: 0 | AM22: 0 | AN22: 0 | AO22: 0 | AP22: 0 | AQ22: 0 | AR22: 0 | AS22: 0 | AT22: 0 | AU22: 0 | AV22: 0 | AW22: 0 | AX22: 0 | AY22: 0 | AZ22: 0 | BA22: 0 | BB22: 0 | BC22: 0 | BD22: 0 | BE22: 0 | BF22: 0 | BG22: 0 | BH22: 0 | BI22: 0 | BJ22: 0 | BK22: 0 | BL22: 0 | BM22: 0 | BN22: 0
A23: 21 | B23: Tomorqasida issiqxona tashkil etgan xonadonlar | C23: =SUM(D23:BN23) -> 602 | D23: 8 | E23: 8 | F23: 22 | G23: 11 | H23: 5 | I23: 28 | J23: 2 | K23: 3 | L23: 31 | M23: 17 | N23: 4 | O23: 6 | P23: 2 | Q23: 12 | R23: 5 | S23: 8 | T23: 3 | U23: 17 | V23: 6 | W23: 3 | X23: 3 | Y23: 6 | Z23: 9 | AA23: 0 | AB23: 2 | AC23: 5 | AD23: 5 | AE23: 8 | AF23: 17 | AG23: 11 | AH23: 5 | AI23: 1 | AJ23: 5 | AK23: 11 | AL23: 4 | AM23: 64 | AN23: 14 | AO23: 11 | AP23: 3 | AQ23: 29 | AR23: 0 | AS23: 0 | AT23: 0 | AU23: 0 | AV23: 3 | AW23: 80 | AX23: 3 | AY23: 0 | AZ23: 0 | BA23: 5 | BB23: 8 | BC23: 2 | BD23: 2 | BE23: 8 | BF23: 10 | BG23: 14 | BH23: 6 | BI23: 12 | BJ23: 6 | BK23: 5 | BL23: 16 | BM23: 7 | BN23: 1
A24: 22 | B24: 2026 yil bahor va kuz mavsumida mevali va manzarali ko‘chat ekish rejasi | C24: =SUBTOTAL(9,D24:BN24) -> 128243 | D24: =SUM(D25:D26) -> 2827 | E24: =SUM(E25:E26) -> 2712 | F24: =SUM(F25:F26) -> 2615 | G24: =SUM(G25:G26) -> 1800 | H24: =SUM(H25:H26) -> 1610 | I24: =SUM(I25:I26) -> 1852 | J24: =SUM(J25:J26) -> 2112 | K24: =SUM(K25:K26) -> 1737 | ... BN24: =SUM(BN25:BN26) -> 1570
A25: =+A24+1 -> 23 | B25: mevali | C25: =SUM(D25:BN25) -> 76940 | D25: 1696 | E25: 1627 | F25: 1569 | G25: 1080 | H25: 966 | I25: 1111 | J25: 1267 | K25: 1042 | L25: 2631 | M25: 709 | N25: 984 | O25: 1068 | P25: 997 | Q25: 1560 | R25: 1582 | S25: 1563 | T25: 1036 | U25: 921 | V25: 984 | W25: 1627 | X25: 1569 | Y25: 1344 | Z25: 1296 | AA25: 900 | AB25: 970 | AC25: 1300 | AD25: 889 | AE25: 1513 | AF25: 1050 | AG25: 1014 | AH25: 1201 | AI25: 1098 | AJ25: 801 | AK25: 1348 | AL25: 1128 | AM25: 966 | AN25: 1209 | AO25: 1581 | AP25: 1155 | AQ25: 1668 | AR25: 754 | AS25: 1275 | AT25: 1570 | AU25: 981 | AV25: 1567 | AW25: 1380 | AX25: 1090 | AY25: 1435 | AZ25: 771 | BA25: 940 | BB25: 1081 | BC25: 1075 | BD25: 1093 | BE25: 982 | BF25: 978 | BG25: 922 | BH25: 1632 | BI25: 1570 | BJ25: 1731 | BK25: 1149 | BL25: 1227 | BM25: 775 | BN25: 942
A26: =+A25+1 -> 24 | B26: manzarali | C26: =SUM(D26:BN26) -> 51303 | D26: 1131 | E26: 1085 | F26: 1046 | G26: 720 | H26: 644 | I26: 741 | J26: 845 | K26: 695 | L26: 1754 | M26: 473 | N26: 656 | O26: 712 | P26: 665 | Q26: 1040 | R26: 1055 | S26: 1042 | T26: 691 | U26: 614 | V26: 656 | W26: 1085 | X26: 1046 | Y26: 896 | Z26: 864 | AA26: 600 | AB26: 647 | AC26: 867 | AD26: 593 | AE26: 1009 | AF26: 700 | AG26: 676 | AH26: 801 | AI26: 732 | AJ26: 534 | AK26: 899 | AL26: 752 | AM26: 644 | AN26: 806 | AO26: 1054 | AP26: 770 | AQ26: 1112 | AR26: 503 | AS26: 850 | AT26: 1047 | AU26: 654 | AV26: 1045 | AW26: 920 | AX26: 727 | AY26: 957 | AZ26: 514 | BA26: 627 | BB26: 721 | BC26: 717 | BD26: 729 | BE26: 655 | BF26: 652 | BG26: 615 | BH26: 1088 | BI26: 1047 | BJ26: 1154 | BK26: 766 | BL26: 818 | BM26: 517 | BN26: 628
A27: II. Demografik ko‘rsatkichlar (soni) | C27: =SUBTOTAL(9,D27:BN27) -> 240967 | D27: =SUM(D28) -> 5214 | E27: =SUM(E28) -> 3662 | F27: =SUM(F28) -> 4165 | G27: =SUM(G28) -> 3633 | H27: =SUM(H28) -> 3900 | I27: =SUM(I28) -> 4727 | J27: =SUM(J28) -> 3697 | K27: =SUM(K28) -> 3437 | ... BN27: =SUM(BN28) -> 2960
A28: 25 | B28: Aholi soni: | C28: =SUBTOTAL(9,D28:BN28) -> 240967 | D28: =SUM(D29:D30) -> 5214 | E28: =SUM(E29:E30) -> 3662 | F28: =SUM(F29:F30) -> 4165 | G28: =SUM(G29:G30) -> 3633 | H28: =SUM(H29:H30) -> 3900 | I28: =SUM(I29:I30) -> 4727 | J28: =SUM(J29:J30) -> 3697 | K28: =SUM(K29:K30) -> 3437 | ... BN28: =SUM(BN29:BN30) -> 2960
A29: =+A28+1 -> 26 | B29: erkaklar | C29: =SUM(D29:BN29) -> 132523 | D29: 2867 | E29: 2014 | F29: 2290 | G29: 1998 | H29: 2145 | I29: 2599 | J29: 2033 | K29: 1890 | L29: 3433 | M29: 1636 | N29: 2004 | O29: 2402 | P29: 2337 | Q29: 3180 | R29: 2351 | S29: 3039 | T29: 1831 | U29: 1851 | V29: 2078 | W29: 2173 | X29: 2646 | Y29: 1778 | Z29: 2040 | AA29: 1386 | AB29: 1567 | AC29: 2178 | AD29: 1694 | AE29: 2345 | AF29: 2220 | AG29: 1932 | AH29: 1832 | AI29: 1615 | AJ29: 1360 | AK29: 1203 | AL29: 1210 | AM29: 2099 | AN29: 1818 | AO29: 2357 | AP29: 2054 | AQ29: 2626 | AR29: 1123 | AS29: 1842 | AT29: 1791 | AU29: 2125 | AV29: 2620 | AW29: 2557 | AX29: 2301 | AY29: 3318 | AZ29: 1658 | BA29: 1654 | BB29: 1983 | BC29: 2365 | BD29: 2356 | BE29: 2120 | BF29: 1802 | BG29: 1790 | BH29: 2771 | BI29: 2148 | BJ29: 2337 | BK29: 1961 | BL29: 2364 | BM29: 1798 | BN29: 1628
A30: =+A29+1 -> 27 | B30: ayollar | C30: =SUM(D30:BN30) -> 108444 | D30: 2347 | E30: 1648 | F30: 1875 | G30: 1635 | H30: 1755 | I30: 2128 | J30: 1664 | K30: 1547 | L30: 2809 | M30: 1339 | N30: 1641 | O30: 1966 | P30: 1913 | Q30: 2602 | R30: 1925 | S30: 2487 | T30: 1499 | U30: 1516 | V30: 1701 | W30: 1779 | X30: 2165 | Y30: 1456 | Z30: 1670 | AA30: 1134 | AB30: 1283 | AC30: 1782 | AD30: 1386 | AE30: 1919 | AF30: 1780 | AG30: 1582 | AH30: 1500 | AI30: 1322 | AJ30: 1114 | AK30: 986 | AL30: 990 | AM30: 1718 | AN30: 1488 | AO30: 1930 | AP30: 1682 | AQ30: 2150 | AR30: 919 | AS30: 1508 | AT30: 1466 | AU30: 1740 | AV30: 2145 | AW30: 2093 | AX30: 1884 | AY30: 2716 | AZ30: 1357 | BA30: 1354 | BB30: 1624 | BC30: 1935 | BD30: 1928 | BE30: 1736 | BF30: 1476 | BG30: 1466 | BH30: 2268 | BI30: 1759 | BJ30: 1913 | BK30: 1605 | BL30: 1935 | BM30: 1472 | BN30: 1332
B31: Yosh toifasi bo‘yicha: | C31: =SUM(D31:BN31) -> 0
A32: =+A30+1 -> 28 | B32: maktab yoshigacha bo‘lgan bolalar (0-6 yosh) | C32: =SUM(D32:BN32) -> 19251 | D32: 417 | E32: 292 | F32: 333 | G32: 290 | H32: 312 | I32: 378 | J32: 295 | K32: 274 | L32: 499 | M32: 238 | N32: 291 | O32: 349 | P32: 340 | Q32: 462 | R32: 342 | S32: 442 | T32: 266 | U32: 269 | V32: 302 | W32: 316 | X32: 384 | Y32: 258 | Z32: 296 | AA32: 201 | AB32: 228 | AC32: 316 | AD32: 246 | AE32: 341 | AF32: 320 | AG32: 281 | AH32: 266 | AI32: 234 | AJ32: 197 | AK32: 175 | AL32: 176 | AM32: 305 | AN32: 264 | AO32: 342 | AP32: 298 | AQ32: 382 | AR32: 163 | AS32: 268 | AT32: 260 | AU32: 309 | AV32: 381 | AW32: 372 | AX32: 334 | AY32: 482 | AZ32: 241 | BA32: 240 | BB32: 288 | BC32: 344 | BD32: 342 | BE32: 308 | BF32: 262 | BG32: 260 | BH32: 403 | BI32: 312 | BJ32: 340 | BK32: 285 | BL32: 343 | BM32: 261 | BN32: 236
A33: =+A32+1 -> 29 | B33: voyaga yetmaganlar (0-18 yosh) | C33: =SUM(D33:BN33) -> 48173 | D33: 1042 | E33: 732 | F33: 833 | G33: 726 | H33: 780 | I33: 945 | J33: 739 | K33: 687 | L33: 1248 | M33: 595 | N33: 729 | O33: 873 | P33: 850 | Q33: 1156 | R33: 855 | S33: 1105 | T33: 666 | U33: 673 | V33: 755 | W33: 790 | X33: 961 | Y33: 646 | Z33: 742 | AA33: 504 | AB33: 570 | AC33: 792 | AD33: 616 | AE33: 852 | AF33: 800 | AG33: 702 | AH33: 666 | AI33: 587 | AJ33: 494 | AK33: 437 | AL33: 440 | AM33: 763 | AN33: 661 | AO33: 857 | AP33: 747 | AQ33: 955 | AR33: 408 | AS33: 670 | AT33: 651 | AU33: 773 | AV33: 953 | AW33: 930 | AX33: 837 | AY33: 1206 | AZ33: 603 | BA33: 601 | BB33: 721 | BC33: 860 | BD33: 856 | BE33: 771 | BF33: 655 | BG33: 651 | BH33: 1007 | BI33: 781 | BJ33: 850 | BK33: 713 | BL33: 859 | BM33: 654 | BN33: 592
A34: =+A33+1 -> 30 | B34: yoshlar (14-30 yosh) | C34: =SUM(D34:BN34) -> 63988 | D34: 1240 | E34: 976 | F34: 1047 | G34: 996 | H34: 1094 | I34: 1329 | J34: 1315 | K34: 868 | L34: 1307 | M34: 626 | N34: 1294 | O34: 1163 | P34: 1097 | Q34: 1585 | R34: 821 | S34: 1193 | T34: 919 | U34: 967 | V34: 957 | W34: 928 | X34: 1309 | Y34: 1171 | Z34: 1092 | AA34: 530 | AB34: 647 | AC34: 1072 | AD34: 705 | AE34: 1478 | AF34: 966 | AG34: 890 | AH34: 1038 | AI34: 961 | AJ34: 779 | AK34: 709 | AL34: 702 | AM34: 1106 | AN34: 966 | AO34: 976 | AP34: 1141 | AQ34: 1187 | AR34: 656 | AS34: 919 | AT34: 826 | AU34: 903 | AV34: 1145 | AW34: 1414 | AX34: 1350 | AY34: 1434 | AZ34: 717 | BA34: 835 | BB34: 1173 | BC34: 935 | BD34: 1115 | BE34: 823 | BF34: 823 | BG34: 1094 | BH34: 920 | BI34: 1150 | BJ34: 1054 | BK34: 673 | BL34: 1315 | BM34: 963 | BN34: 604
A35: =+A34+1 -> 31 | B35: keksalar (60 yosh va undan kattalar) | C35: =SUM(D35:BN35) -> 36119 | D35: 782 | E35: 549 | F35: 624 | G35: 544 | H35: 585 | I35: 709 | J35: 554 | K35: 515 | L35: 936 | M35: 446 | N35: 546 | O35: 655 | P35: 637 | Q35: 867 | R35: 641 | S35: 828 | T35: 499 | U35: 505 | V35: 566 | W35: 592 | X35: 721 | Y35: 485 | Z35: 556 | AA35: 378 | AB35: 427 | AC35: 594 | AD35: 462 | AE35: 639 | AF35: 600 | AG35: 527 | AH35: 499 | AI35: 440 | AJ35: 371 | AK35: 328 | AL35: 330 | AM35: 572 | AN35: 495 | AO35: 643 | AP35: 560 | AQ35: 716 | AR35: 306 | AS35: 502 | AT35: 488 | AU35: 579 | AV35: 714 | AW35: 697 | AX35: 627 | AY35: 905 | AZ35: 452 | BA35: 451 | BB35: 541 | BC35: 645 | BD35: 642 | BE35: 578 | BF35: 491 | BG35: 488 | BH35: 755 | BI35: 586 | BJ35: 637 | BK35: 534 | BL35: 644 | BM35: 490 | BN35: 444
A36: III. Aholining etnik tarkibi(soni): | C36: =SUBTOTAL(9,D36:BN36) -> 240967 | D36: =SUM(D37:D47) -> 5214 | E36: =SUM(E37:E47) -> 3662 | F36: =SUM(F37:F47) -> 4165 | G36: =SUM(G37:G47) -> 3633 | H36: =SUM(H37:H47) -> 3900 | I36: =SUM(I37:I47) -> 4727 | J36: =SUM(J37:J47) -> 3697 | K36: =SUM(K37:K47) -> 3437 | ... BN36: =SUM(BN37:BN47) -> 2960
A37: =+A35+1 -> 32 | B37: o‘zbek | C37: =SUM(D37:BN37) -> 217812 | D37: 4986 | E37: 3599 | F37: 4113 | G37: 3380 | H37: 3520 | I37: 4302 | J37: 3686 | K37: 3021 | L37: 6042 | M37: 2920 | N37: 3585 | O37: 4238 | P37: 4196 | Q37: 5728 | R37: 4198 | S37: 5476 | T37: 3321 | U37: 3330 | V37: 3775 | W37: 3915 | X37: 4399 | Y37: 3109 | Z37: 3674 | AA37: 2210 | AB37: 2433 | AC37: 3920 | AD37: 2916 | AE37: 3723 | AF37: 3411 | AG37: 3484 | AH37: 3212 | AI37: 1179 | AJ37: 1272 | AK37: 2107 | AL37: 1621 | AM37: 3304 | AN37: 2936 | AO37: 4195 | AP37: 3379 | AQ37: 4475 | AR37: 936 | AS37: 2713 | AT37: 2343 | AU37: 3354 | AV37: 4678 | AW37: 4628 | AX37: 4132 | AY37: 5815 | AZ37: 1795 | BA37: 2713 | BB37: 3316 | BC37: 2917 | BD37: 3900 | BE37: 3765 | BF37: 2894 | BG37: 1540 | BH37: 3748 | BI37: 3436 | BJ37: 3737 | BK37: 3247 | BL37: 4271 | BM37: 2769 | BN37: 2875
A38: =+A37+1 -> 33 | B38: qoraqalpoq | C38: =SUM(D38:BN38) -> 151 | D38: 0 | E38: 0 | F38: 8 | G38: 0 | H38: 0 | I38: 0 | J38: 0 | K38: 1 | L38: 0 | M38: 0 | N38: 0 | O38: 0 | P38: 0 | Q38: 0 | R38: 0 | S38: 0 | T38: 0 | U38: 0 | V38: 0 | W38: 0 | X38: 5 | Y38: 0 | Z38: 5 | AA38: 8 | AB38: 0 | AC38: 0 | AD38: 4 | AE38: 8 | AF38: 5 | AG38: 0 | AH38: 0 | AI38: 2 | AJ38: 0 | AK38: 0 | AL38: 0 | AM38: 0 | AN38: 4 | AO38: 0 | AP38: 0 | AQ38: 0 | AR38: 12 | AS38: 2 | AT38: 42 | AU38: 0 | AV38: 0 | AW38: 3 | AX38: 0 | AY38: 4 | AZ38: 0 | BA38: 0 | BB38: 2 | BC38: 0 | BD38: 11 | BE38: 0 | BF38: 11 | BG38: 0 | BH38: 4 | BI38: 0 | BJ38: 0 | BK38: 0 | BL38: 0 | BM38: 0 | BN38: 10
A39: =+A38+1 -> 34 | B39: rus | C39: =SUM(D39:BN39) -> 1241 | D39: 4 | E39: 0 | F39: 3 | G39: 3 | H39: 0 | I39: 0 | J39: 1 | K39: 8 | L39: 0 | M39: 8 | N39: 0 | O39: 0 | P39: 2 | Q39: 0 | R39: 0 | S39: 0 | T39: 1 | U39: 1 | V39: 1 | W39: 0 | X39: 5 | Y39: 4 | Z39: 7 | AA39: 58 | AB39: 72 | AC39: 1 | AD39: 0 | AE39: 2 | AF39: 0 | AG39: 1 | AH39: 15 | AI39: 0 | AJ39: 5 | AK39: 12 | AL39: 147 | AM39: 37 | AN39: 102 | AO39: 1 | AP39: 17 | AQ39: 16 | AR39: 159 | AS39: 325 | AT39: 1 | AU39: 0 | AV39: 3 | AW39: 8 | AX39: 1 | AY39: 37 | AZ39: 4 | BA39: 10 | BB39: 42 | BC39: 1 | BD39: 5 | BE39: 50 | BF39: 5 | BG39: 0 | BH39: 2 | BI39: 0 | BJ39: 37 | BK39: 1 | BL39: 0 | BM39: 13 | BN39: 3
A40: =+A39+1 -> 35 | B40: qirg‘iz | C40: =SUM(D40:BN40) -> 83 | D40: 0 | E40: 0 | F40: 0 | G40: 0 | H40: 0 | I40: 0 | J40: 0 | K40: 0 | L40: 0 | M40: 0 | N40: 0 | O40: 0 | P40: 39 | Q40: 0 | R40: 6 | S40: 0 | T40: 0 | U40: 0 | V40: 0 | W40: 2 | X40: 0 | Y40: 0 | Z40: 0 | AA40: 24 | AB40: 0 | AC40: 0 | AD40: 0 | AE40: 0 | AF40: 0 | AG40: 0 | AH40: 0 | AI40: 1 | AJ40: 0 | AK40: 0 | AL40: 0 | AM40: 0 | AN40: 0 | AO40: 0 | AP40: 0 | AQ40: 2 | AR40: 2 | AS40: 4 | AT40: 2 | AU40: 1 | AV40: 0 | AW40: 0 | AX40: 0 | AY40: 0 | AZ40: 0 | BA40: 0 | BB40: 0 | BC40: 0 | BD40: 0 | BE40: 0 | BF40: 0 | BG40: 0 | BH40: 0 | BI40: 0 | BJ40: 0 | BK40: 0 | BL40: 0 | BM40: 0 | BN40: 0
...

Sheet Лист2
A4: 0/6 | C4: 417 | D4: 292 | E4: 333 | F4: 290 | G4: 312 | H4: 378 | I4: 295 | J4: 274 | K4: 499 | L4: 238 | M4: 291 | N4: 349 | O4: 340 | P4: 462 | Q4: 342 | R4: 442 | S4: 266 | T4: 269 | U4: 302 | V4: 316 | W4: 384 | X4: 258 | Y4: 296 | Z4: 201 | AA4: 228 | AB4: 316 | AC4: 246 | AD4: 341 | AE4: 320 | AF4: 281 | AG4: 266 | AH4: 234 | AI4: 197 | AJ4: 175 | AK4: 176 | AL4: 305 | AM4: 264 | AN4: 342 | AO4: 298 | AP4: 382 | AQ4: 163 | AR4: 268 | AS4: 260 | AT4: 309 | AU4: 381 | AV4: 372 | AW4: 334 | AX4: 482 | AY4: 241 | AZ4: 240 | BA4: 288 | BB4: 344 | BC4: 342 | BD4: 308 | BE4: 262 | BF4: 260 | BG4: 403 | BH4: 312 | BI4: 340 | BJ4: 285 | BK4: 343 | BL4: 261 | BM4: 236
C5: 1042 | D5: 732 | E5: 833 | F5: 726 | G5: 780 | H5: 945 | I5: 739 | J5: 687 | K5: 1248 | L5: 595 | M5: 729 | N5: 873 | O5: 850 | P5: 1156 | Q5: 855 | R5: 1105 | S5: 666 | T5: 673 | U5: 755 | V5: 790 | W5: 961 | X5: 646 | Y5: 742 | Z5: 504 | AA5: 570 | AB5: 792 | AC5: 616 | AD5: 852 | AE5: 800 | AF5: 702 | AG5: 666 | AH5: 587 | AI5: 494 | AJ5: 437 | AK5: 440 | AL5: 763 | AM5: 661 | AN5: 857 | AO5: 747 | AP5: 955 | AQ5: 408 | AR5: 670 | AS5: 651 | AT5: 773 | AU5: 953 | AV5: 930 | AW5: 837 | AX5: 1206 | AY5: 603 | AZ5: 601 | BA5: 721 | BB5: 860 | BC5: 856 | BD5: 771 | BE5: 655 | BF5: 651 | BG5: 1007 | BH5: 781 | BI5: 850 | BJ5: 713 | BK5: 859 | BL5: 654 | BM5: 592
C6: =C5-C4 -> 625 | D6: =D5-D4 -> 440 | E6: =E5-E4 -> 500 | F6: =F5-F4 -> 436 | G6: =G5-G4 -> 468 | H6: =H5-H4 -> 567 | I6: =I5-I4 -> 444 | J6: =J5-J4 -> 413 | ... BM6: =BM5-BM4 -> 356
